Workbook

Sheet Summary
A2: Rebaseline
A3: Scope | B3: Category | C3: Emission Source | D3: Included (Y/N) | E3: H1 FY25 tCO2e Market | F3: H1 FY25 tCO2e Location | G3: FY24 tCO2e Market | H3: FY 24 tCO2e Location | I3: FY 23 tCO2e Market | J3: FY 23 tCO2e Location | K3: FY22 tCO2e Market | L3: FY22 tCO2e Location
A4: 1 | B4: - | C4: Stationary combustion | D4: Y | E4: 1336.419 | F4: 1336.419 | G4: 1736.4822 | H4: 1736.4822 | I4: 1355.3302 | J4: 1355.3302 | K4: 1408.5867 | L4: 1408.5867
A5: 1 | B5: - | C5: Company vehicles | D5: Y | E5: 936.81688 | F5: 936.81688 | G5: 2120.6171 | H5: 2120.6171 | I5: 1917.79 | J5: 1917.79 | K5: 825.72832 | L5: 825.72832
A6: 1 | B6: - | C6: Fugitive emissions | D6: N | E6: 0 | F6: 0 | G6: 0 | H6: 0 | I6: 0 | J6: 0 | K6: 0 | L6: 0
A7: 1 | B7: - | C7: Refrigerants | D7: Y | E7: 6.410566 | F7: 6.410566 | G7: 18.080351 | H7: 18.080351 | I7: 1.5385 | J7: 1.5385 | K7: 1.6471 | L7: 1.6471
A8: 1 | C8: Scope 1 Extrapolation | D8: N | E8: 0 | F8: 0 | G8: 0 | H8: 0 | I8: 328.95312 | J8: 328.95312 | K8: 1333.8499 | L8: 1333.8499
A9: 2 | B9: - | C9: Electricity usage | D9: Y | E9: 3365.3929 | F9: 2757.2595 | G9: 3667.1893 | H9: 5692.5506 | I9: 5272.9372 | J9: 4764.3818 | K9: 4520.5869 | L9: 4279.6023
A10: 2 | B10: - | C10: Heating | D10: Y | E10: 53.952952 | F10: 53.952952 | G10: 139.6637 | H10: 139.6637 | I10: 53.555697 | J10: 53.555697 | K10: 0 | L10: 0
A11: 2 | B11: - | C11: Cooling | D11: N | E11: 0 | F11: 0 | G11: 0 | H11: 0 | I11: 0 | J11: 0 | K11: 0 | L11: 0
A12: 2 | C12: Scope 2 Extrapolation | D12: N | E12: 0 | F12: 0 | G12: 0 | H12: 0 | I12: 1023.98 | J12: 1250.3916 | K12: 1329.2162 | L12: 1338.9516
A13: 3 | B13: 1 | C13: Purchased goods and services | D13: Y | E13: 79412.202 | F13: 79412.202 | G13: 176935.41 | H13: 176935.41 | I13: 191705.14 | J13: 191705.14 | K13: 154151.64 | L13: 154151.64
A14: 3 | B14: 2 | C14: Capital goods | D14: Y | E14: 1553.4786 | F14: 1553.4786 | G14: 6973.2078 | H14: 6973.2078 | I14: 8445.8016 | J14: 8445.8016 | K14: 5971.4072 | L14: 5971.4072
A15: 3 | B15: 3 | C15: Fuel and energy related activities | D15: Y | E15: 1173.4546 | F15: 1173.4546 | G15: 2303.622 | H15: 2303.622 | I15: 2299.2305 | J15: 2299.2305 | K15: 2160.8372 | L15: 2160.8372
A16: 3 | B16: 4 | C16: Upstream transportation and distribution | D16: Y | E16: 22660.451 | F16: 22660.451 | G16: 38920.499 | H16: 38920.499 | I16: 41103.353 | J16: 41103.353 | K16: 42362.16 | L16: 42362.16
A17: 3 | B17: 5 | C17: Waste generated in operations | D17: Y | E17: 398.82427 | F17: 398.82427 | G17: 625.92365 | H17: 625.92365 | I17: 721.55269 | J17: 721.55269 | K17: 464.9853 | L17: 464.9853
A18: 3 | B18: 6 | C18: Business travel | D18: Y | E18: 3171.7995 | F18: 3171.7995 | G18: 6734.7391 | H18: 6734.7391 | I18: 6514.0033 | J18: 6514.0033 | K18: 5708.7733 | L18: 5708.7733
A19: 3 | B19: 7 | C19: Employee commuting | D19: Y | E19: 3379.0944 | F19: 3379.0944 | G19: 6955.0292 | H19: 6955.0292 | I19: 6123.1243 | J19: 6123.1243 | K19: 5166.7426 | L19: 5166.7426
A20: 3 | B20: 8 | C20: Upstream leased assets | D20: Y | E20: 1436.436 | F20: 1436.436 | G20: 2922.6612 | H20: 2922.6612 | I20: 2800.9244 | J20: 2800.9244 | K20: 2691.9199 | L20: 2691.9199
A21: 3 | B21: 9 | C21: Downstream transportation and distribution | D21: N | E21: 0 | F21: 0 | G21: 0 | H21: 0 | I21: 0 | J21: 0 | K21: 0 | L21: 0
A22: 3 | B22: 10 | C22: Processing of sold products | D22: N | E22: 0 | F22: 0 | G22: 0 | H22: 0 | I22: 0 | J22: 0 | K22: 0 | L22: 0
A23: 3 | B23: 11 | C23: Use of sold products | D23: Y | E23: 861.11502 | F23: 861.11502 | G23: 1722.23 | H23: 1722.23 | I23: 1722.23 | J23: 1722.23 | K23: 1722.23 | L23: 1722.23
A24: 3 | B24: 12 | C24: End of life treatment of sold products | D24: Y | E24: 20.476429 | F24: 20.476429 | G24: 41.126644 | H24: 41.126644 | I24: 93.945599 | J24: 93.945599 | K24: 95.631573 | L24: 95.631573
... A27: 3 | B27: 15 | C27: Investments | D27: N | E27: 0 | F27: 0 | G27: 0 | H27: 0 | I27: 0 | J27: 0 | K27: 0 | L27: 0
A28: Total | E28: 119766.32 | F28: 119158.19 | G28: 251816.48 | H28: 253841.84 | I28: 271483.39 | J28: 271201.24 | K28: 229915.94 | L28: 229684.69
A31: Original
A32: Scope | B32: Category | C32: Emission Source | E32: H1 FY25 tCO2e Market | F32: H1 FY25 tCO2e Location | G32: FY24 tCO2e Market | H32: FY 24 tCO2e Location | I32: FY23 Original Market | J32: FY23 Original Location | K32: FY22 Original | L32: FY22 Original
A33: 1 | B33: - | C33: Total Scope 1 | E33: N/A | F33: N/A | G33: N/A | H33: N/A | I33: 3351 | J33: 3351 | K33: 2443 | L33: 2443
A34: 2 | B34: - | C34: Total Scope 2 | E34: N/A | F34: N/A | G34: N/A | H34: N/A | I34: 5585.1041 | J34: 4953.291 | K34: 4806 | L34: 4557.67
A35: 3 | B35: 1 | C35: Purchased goods and services | E35: N/A | F35: N/A | G35: N/A | H35: N/A | I35: 81338 | J35: 81338 | K35: 101436 | L35: 101436
A36: 3 | B36: 2 | C36: Capital goods | E36: N/A | F36: N/A | G36: N/A | H36: N/A | I36: 14113 | J36: 14113 | K36: 12431 | L36: 12431
A37: 3 | B37: 3 | C37: Fuel and energy related activities | E37: N/A | F37: N/A | G37: N/A | H37: N/A | I37: 1915 | J37: 1915 | K37: 1705 | L37: 1705
A38: 3 | B38: 4 | C38: Upstream transportation and distribution | E38: N/A | F38: N/A | G38: N/A | H38: N/A | I38: 38779 | J38: 38779 | K38: 67200 | L38: 67200
A39: 3 | B39: 5 | C39: Waste generated in operations | E39: N/A | F39: N/A | G39: N/A | H39: N/A | I39: 1816 | J39: 1816 | K39: 1499 | L39: 1499
A40: 3 | B40: 6 | C40: Business travel | E40: N/A | F40: N/A | G40: N/A | H40: N/A | I40: 7253 | J40: 7253 | K40: 8889 | L40: 8889
A41: 3 | B41: 7 | C41: Employee commuting | E41: N/A | F41: N/A | G41: N/A | H41: N/A | I41: 3258 | J41: 3258 | K41: 2972 | L41: 2972
A42: 3 | B42: 8 | C42: Upstream leased assets | E42: N/A | F42: N/A | G42: N/A | H42: N/A | I42: 0 | J42: 0 | K42: 0 | L42: 0
A43: 3 | B43: 9 | C43: Downstream transportation and distribution | E43: N/A | F43: N/A | G43: N/A | H43: N/A | I43: 0 | J43: 0 | K43: 0 | L43: 0
A44: 3 | B44: 10 | C44: Processing of sold products | E44: N/A | F44: N/A | G44: N/A | H44: N/A | I44: 0 | J44: 0 | K44: 0 | L44: 0
A45: 3 | B45: 11 | C45: Use of sold products | E45: N/A | F45: N/A | G45: N/A | H45: N/A | I45: 2173 | J45: 2173 | K45: 1567 | L45: 1567
...

Sheet FY25 H1
B2: FY25 H1 Footprint by Entity Code
B4: Scope | C4: Category | D4: Upstream/Downstream | E4: Emission Source | F4: Diploma Total | G4: G3010 | H4: L2050 | I4: L3015 | J4: S7030 | K4: S7040 | L4: S7060 | M4: S7090 | N4: S6040 | O4: G5020 | P4: L2010 | Q4: L2020 | R4: L2030 | S4: L2040 | T4: S2050 | U4: S2060 | V4: C5520 | W4: S4030 | X4: G5040 | Y4: L2500 | Z4: L7010 | AA4: S4010 | AB4: C2540 | AC4: C4050 | AD4: C2090 | AE4: C2091 | AF4: c4030 | AG4: C7010 | AH4: G3045 | AI4: L2090 | AJ4: L5010 | AK4: S1030 | AL4: G5025 | AM4: HoIntSealsE | AN4: S1040 | AO4: S2210 | AP4: S7020 | AQ4: L2060 | AR4: L3025 | AS4: L7030 | AT4: S1010 | AU4: L2510 | AV4: L2700 | AW4: L7020 | AX4: S4020 | AY4: S6020 | AZ4: S6070 | BA4: C2530 | BB4: c1010 | BC4: C1040 | BD4: C2040 | BE4: C2041 | BF4: C2042 | BG4: C2043 | BH4: C2080 | BI4: C2551 | BJ4: C2552 | BK4: C2553 | BL4: C2554 | BM4: C2555 | BN4: C3510 | BO4: C5010 | BP4: C6020 | BQ4: C8010 | BR4: C9010 | BS4: C9050 | BT4: G2010 | BU4: G3015 | BV4: G3020 | BW4: G3041 | BX4: G4010 | BY4: G5005 | BZ4: G5010 | CA4: HoControls | CB4: HoGrp | CC4: HoIntSeals | CD4: HoLS | CE4: L5020 | CF4: R1100 | CG4: R1120 | CH4: R1140 | CI4: R1170 | CJ4: R1180 | CK4: R1190 | CL4: R1210 | CM4: R1220 | CN4: R1230 | CO4: R1240 | CP4: R2100 | CQ4: R2110 | CR4: R2120 | CS4: R2130 | CT4: R2150 | CU4: R2160 | CV4: R2170 | CW4: R2180 | CX4: R2190 | CY4: R2210 | CZ4: R2220 | DA4: R3100 | DB4: R4100 | DC4: R4110 | DD4: R4120 | DE4: R4130 | DF4: R4140 | DG4: R4150 | DH4: R4160 | DI4: R5100 | DJ4: R5110 | DK4: R5120 | DL4: R9100 | DM4: S3010 | DN4: S3030 | DO4: S4040 | DP4: S4050 | DQ4: S9010 | DR4: C1510 | DS4: C1520 | DT4: C1530 | DU4: C2045 | DV4: C2046 | DW4: C2571 | DX4: C2572 | DY4: C2573 | DZ4: C2574 | EA4: C2575 | EB4: C2576 | EC4: C2577 | ED4: C2578 | EE4: C3040 | EF4: C4510 | EG4: C5510 | EH4: C8500 | EI4: G3025 | EJ4: G5015 | EK4: HoControlsU | EL4: HoDHI | EM4: HoLSU | EN4: HoNaSeals | EO4: LCAoem | EP4: S1020 | EQ4: S2010 | ER4: S2025 | ES4: S2026 | ET4: S2310 | EU4: S8010 | EV4: S8020 | EW4: S8030 | EX4: C1050 | EY4: HoLSC | EZ4: HoLSDCHI
B5: 1 | C5: - | D5: Internal | E5: All Scope 1 | F5: 2279.6464 | G5: 0 | H5: 0 | I5: 0 | J5: 25.806701 | K5: 0 | L5: 175.90592 | M5: 0 | N5: 0 | O5: 0 | P5: 0 | Q5: 46.336699 | R5: 0 | S5: 76.030307 | T5: 1.4696002 | U5: 0.23063682 | V5: 0 | W5: 0 | X5: 0 | Y5: 42.559856 | Z5: 0 | AA5: 7.3909522 | AB5: 0 | AC5: 0 | AD5: 7.9714473 | AE5: 0 | AF5: 50.750081 | AG5: 11.380546 | AH5: 0 | AI5: 64.843237 | AJ5: 201.5569 | AK5: 14.553844 | AL5: 0 | AM5: 0 | AN5: 0 | AO5: 11.157766 | AP5: 1.5031316 | AQ5: 0 | AR5: 4.1364233 | AS5: 0 | AT5: 41.353875 | AU5: 0 | AV5: 28.08464 | AW5: 0 | AX5: 3.7431061 | AY5: 0 | AZ5: 0 | BA5: 0 | BB5: 7.619832 | BC5: 0 | BD5: 26.69327 | BE5: 0 | BF5: 0 | BG5: 0 | BH5: 22.008105 | BI5: 0 | BJ5: 0 | BK5: 0 | BL5: 0 | BM5: 0 | BN5: 0 | BO5: 0 | BP5: 0 | BQ5: 4.9854103 | BR5: 0 | BS5: 0.91236779 | BT5: 0 | BU5: 0 | BV5: 0 | BW5: 0 | BX5: 0 | BY5: 0 | BZ5: 0 | CA5: 0 | CB5: 0 | CC5: 0 | CD5: 0 | CE5: 9.7825271 | CF5: 0 | CG5: 0 | CH5: 0 | CI5: 55.849459 | CJ5: 34.147693 | CK5: 103.71384 | CL5: 5.7413865 | CM5: 31.453037 | CN5: 15.159629 | CO5: 0 | CP5: 0 | CQ5: 2.0459856 | CR5: 11.430266 | CS5: 38.537621 | CT5: 23.835095 | CU5: 1.3946236 | CV5: 12.399258 | CW5: 3.9694787 | CX5: 6.956272 | CY5: 15.502602 | CZ5: 0 | DA5: 0 | DB5: 3.8866804 | DC5: 0.080546 | DD5: 6.051055 | DE5: 5.7849274 | DF5: 0 | DG5: 4.0654471 | DH5: 40.613292 | DI5: 12.163572 | DJ5: 0 | DK5: 0 | DL5: 0 | DM5: 16.774316 | DN5: 0.0065844 | DO5: 9.7101472 | DP5: 7.1483213 | DQ5: 9.5661576 | DR5: 18.311 | DS5: 63.81345 | DT5: 28.77252 | DU5: 5.9943694 | DV5: 0 | DW5: 0 | DX5: 0 | DY5: 0 | DZ5: 0 | EA5: 0 | EB5: 0 | EC5: 0 | ED5: 0 | EE5: 0.1558623 | EF5: 0.14248282 | EG5: 42.710661 | EH5: 530.59684 | EI5: 0 | EJ5: 0 | EK5: 0 | EL5: 0 | EM5: 0 | EN5: 0 | EO5: 59.473027 | EP5: 0 | EQ5: 0 | ER5: 55.401292 | ES5: 0 | ET5: 23.28176 | EU5: 35.683393 | EV5: 16.779744 | EW5: 28.806907 | EX5: 2.9686576 | EY5: 0 | EZ5: 0
B6: 2 | C6: - | D6: Internal | E6: All Scope 2 MB | F6: 3419.3459 | G6: 0 | H6: 0 | I6: 82.74892 | J6: 21.247164 | K6: 0 | L6: 39.518139 | M6: 3.594078 | N6: 0 | O6: 0 | P6: 0 | Q6: 10.463418 | R6: 0 | S6: 18.042299 | T6: 5.4453685 | U6: 7.3970685 | V6: 0 | W6: 0 | X6: 0 | Y6: 37.550504 | Z6: 0 | AA6: 89.982221 | AB6: 0 | AC6: 0 | AD6: 15.549907 | AE6: 0 | AF6: 31.360778 | AG6: 13.723513 | AH6: 0 | AI6: 49.014704 | AJ6: 35.981301 | AK6: 4.6702774 | AL6: 0 | AM6: 0 | AN6: 0 | AO6: 2.6228953 | AP6: 0.58796805 | AQ6: 0 | AR6: 1.57833 | AS6: 0 | AT6: 258.20286 | AU6: 0.43670195 | AV6: 3.1972041 | AW6: 0 | AX6: 0.31476658 | AY6: 0 | AZ6: 0 | BA6: 1.6992072 | BB6: 23.187357 | BC6: 0 | BD6: 30.464343 | BE6: 0 | BF6: 0 | BG6: 0 | BH6: 68.546084 | BI6: 0 | BJ6: 0 | BK6: 0 | BL6: 0 | BM6: 0 | BN6: 0 | BO6: 0 | BP6: 0 | BQ6: 127.43111 | BR6: 0 | BS6: 3.8361542 | BT6: 17.159709 | BU6: 0 | BV6: 0 | BW6: 0 | BX6: 0 | BY6: 0 | BZ6: 0 | CA6: 0 | CB6: 0 | CC6: 0 | CD6: 0 | CE6: 0 | CF6: 0 | CG6: 0 | CH6: 0 | CI6: 13.142131 | CJ6: 11.172027 | CK6: 18.527964 | CL6: 3.6740536 | CM6: 15.742265 | CN6: 3.7117483 | CO6: 0 | CP6: 0 | CQ6: 14.261551 | CR6: 8.5153792 | CS6: 4.0319489 | CT6: 41.489791 | CU6: 22.20582 | CV6: 18.066944 | CW6: 3.7495789 | CX6: 3.4566676 | CY6: 3.6611004 | CZ6: 8.2893278 | DA6: 0 | DB6: 6.0801038 | DC6: 5.917536 | DD6: 2.5911626 | DE6: 4.1758139 | DF6: 3.4230473 | DG6: 2.5911626 | DH6: 38.451264 | DI6: 0.87223988 | DJ6: 0 | DK6: 0 | DL6: 0 | DM6: 40.410725 | DN6: 5.8058697 | DO6: 4.1864174 | DP6: 13.943293 | DQ6: 27.181631 | DR6: 10.584665 | DS6: 68.652687 | DT6: 25.413465 | DU6: 14.814487 | DV6: 0 | DW6: 0 | DX6: 0 | DY6: 0 | DZ6: 0 | EA6: 0 | EB6: 0 | EC6: 0 | ED6: 0 | EE6: 2.9510964 | EF6: 7.6743586 | EG6: 16.694828 | EH6: 1396.8837 | EI6: 0 | EJ6: 0 | EK6: 0 | EL6: 0 | EM6: 0 | EN6: 0 | EO6: 87.208839 | EP6: 0 | EQ6: 0 | ER6: 181.30726 | ES6: 0 | ET6: 24.920081 | EU6: 166.89445 | EV6: 33.490128 | EW6: 24.766915 | EX6: 2.2059897 | EY6: 0 | EZ6: 0
B7: 2 | D7: Internal | E7: All Scope 2 LB | F7: 2811.2125 | G7: 0 | H7: 0 | I7: 82.74892 | J7: 21.247164 | K7: 0 | L7: 39.518139 | M7: 3.594078 | N7: 0 | O7: 0 | P7: 0 | Q7: 10.463418 | R7: 0 | S7: 18.042299 | T7: 5.4453685 | U7: 7.3970685 | V7: 0 | W7: 0 | X7: 0 | Y7: 19.209577 | Z7: 0 | AA7: 48.075632 | AB7: 0 | AC7: 0 | AD7: 7.92288 | AE7: 0 | AF7: 15.978725 | AG7: 6.9923084 | AH7: 0 | AI7: 31.917672 | AJ7: 23.430507 | AK7: 2.918424 | AL7: 0 | AM7: 0 | AN7: 0 | AO7: 1.3982087 | AP7: 0.9250271 | AQ7: 0 | AR7: 1.57833 | AS7: 0 | AT7: 156.50452 | AU7: 0.07232 | AV7: 0.5294728 | AW7: 0 | AX7: 0.0521269 | AY7: 0 | AZ7: 0 | BA7: 1.6992072 | BB7: 12.360678 | BC7: 0 | BD7: 16.405335 | BE7: 0 | BF7: 0 | BG7: 0 | BH7: 36.540432 | BI7: 0 | BJ7: 0 | BK7: 0 | BL7: 0 | BM7: 0 | BN7: 0 | BO7: 0 | BP7: 0 | BQ7: 67.930765 | BR7: 0 | BS7: 2.0449707 | BT7: 9.147469 | BU7: 0 | BV7: 0 | BW7: 0 | BX7: 0 | BY7: 0 | BZ7: 0 | CA7: 0 | CB7: 0 | CC7: 0 | CD7: 0 | CE7: 0 | CF7: 0 | CG7: 0 | CH7: 0 | CI7: 7.0057852 | CJ7: 5.9555655 | CK7: 9.8768565 | CL7: 1.9585584 | CM7: 8.3918607 | CN7: 1.9786526 | CO7: 0 | CP7: 0 | CQ7: 7.602524 | CR7: 4.5393642 | CS7: 2.1493446 | CT7: 22.117309 | CU7: 11.837442 | CV7: 9.6310964 | CW7: 1.9988193 | CX7: 1.8426746 | CY7: 1.9516533 | CZ7: 4.4188611 | DA7: 0 | DB7: 4.5661552 | DC7: 3.1545103 | DD7: 1.3812927 | DE7: 2.226036 | DF7: 1.8247524 | DG7: 1.3812927 | DH7: 20.497536 | DI7: 0.46497219 | DJ7: 0 | DK7: 0 | DL7: 0 | DM7: 21.542082 | DN7: 3.0949834 | DO7: 2.2316884 | DP7: 7.4328672 | DQ7: 14.489939 | DR7: 10.157874 | DS7: 69.155729 | DT7: 24.388751 | DU7: 13.31924 | DV7: 0 | DW7: 0 | DX7: 0 | DY7: 0 | DZ7: 0 | EA7: 0 | EB7: 0 | EC7: 0 | ED7: 0 | EE7: 2.8954448 | EF7: 7.5296358 | EG7: 16.379998 | EH7: 1338.3144 | EI7: 0 | EJ7: 0 | EK7: 0 | EL7: 0 | EM7: 0 | EN7: 0 | EO7: 82.766135 | EP7: 0 | EQ7: 0 | ER7: 180.48855 | ES7: 0 | ET7: 23.085985 | EU7: 146.11416 | EV7: 31.505278 | EW7: 24.299862 | EX7: 1.1759653 | EY7: 0 | EZ7: 0
B8: 3 | C8: 1 | D8: Upstream | E8: Purchased goods and services | F8: 79412.202 | G8: 0.8714176 | H8: 856.14424 | I8: 3821.8502 | J8: 579.21649 | K8: -10.316326 | L8: 1300.3478 | M8: 1.0266621 | N8: 65.285235 | O8: 0 | P8: 0 | Q8: 3997.1941 | R8: 0 | S8: 6118.23 | T8: 488.13135 | U8: 624.93159 | V8: 0.08261794 | W8: 5.6895635 | X8: -57.844455 | Y8: 1896.4305 | Z8: 0 | AA8: 428.88079 | AB8: 0.94715867 | AC8: 44.064847 | AD8: 223.29358 | AE8: 137.40119 | AF8: 1081.619 | AG8: 1013.8449 | AH8: 2.0094466 | AI8: 2512.0444 | AJ8: 3261.5603 | AK8: 533.77045 | AL8: 116.19232 | AM8: 0 | AN8: 1.4749546 | AO8: 55.359166 | AP8: 37.597377 | AQ8: 187.01237 | AR8: 527.69624 | AS8: 96.077573 | AT8: 2183.6991 | AU8: 160.05744 | AV8: 1439.2633 | AW8: 0 | AX8: 260.95036 | AY8: 126.97579 | AZ8: 0 | BA8: 1.8249574 | BB8: 815.84054 | BC8: 0.51109164 | BD8: 1115.5842 | BE8: -20.528104 | BF8: 14.795069 | BG8: 67.25831 | BH8: 1507.5798 | BI8: 2.7195855 | BJ8: 2.9037274 | BK8: 0.23713409 | BL8: 1.7489347 | BM8: 1.3062513 | BN8: 390.03145 | BO8: 0 | BP8: 0 | BQ8: 456.32756 | BR8: 1080.5179 | BS8: 420.11868 | BT8: 824.76992 | BU8: 0 | BV8: 0.058196984 | BW8: 0.014047579 | BX8: 0.63661389 | BY8: 0 | BZ8: 2464.2223 | CA8: 434.5339 | CB8: -6.7118907 | CC8: 0.14039964 | CD8: -177.68309 | CE8: 349.52311 | CF8: 0 | CG8: 0 | CH8: 0 | CI8: 159.91902 | CJ8: 198.78936 | CK8: 513.94834 | CL8: 123.57497 | CM8: 180.38769 | CN8: 95.057645 | CO8: 0 | CP8: 0 | CQ8: 404.63974 | CR8: 380.44395 | CS8: 202.46653 | CT8: 566.3848 | CU8: -10.88296 | CV8: 108.61213 | CW8: 191.86251 | CX8: 84.370373 | CY8: 372.99607 | CZ8: 31.188651 | DA8: 185.95134 | DB8: 67.194707 | DC8: 19.025834 | DD8: 34.661021 | DE8: 82.387647 | DF8: 60.955967 | DG8: 45.583356 | DH8: 708.63212 | DI8: 75.305366 | DJ8: 0.32175688 | DK8: 0 | DL8: 0 | DM8: 271.80162 | DN8: 33.421592 | DO8: 31.286948 | DP8: 213.5727 | DQ8: 88.396998 | DR8: 362.72184 | DS8: 658.8293 | DT8: 225.22525 | DU8: 1002.4266 | DV8: 648.47658 | DW8: 18.125283 | DX8: 2.5763415 | DY8: 15.550886 | DZ8: 2.6657774 | EA8: 6.7363405 | EB8: 30.884277 | EC8: 7.4851807 | ED8: 1.3582148 | EE8: 227.25597 | EF8: 639.65908 | EG8: 2765.466 | EH8: 392.91741 | EI8: 83.099458 | EJ8: 220.26643 | EK8: -160.92179 | EL8: -53.591333 | EM8: 0 | EN8: 0 | EO8: 8811.9978 | EP8: 92.813925 | EQ8: 94.853924 | ER8: 6029.4358 | ES8: 2.9591872 | ET8: 511.62 | EU8: 6671.2089 | EV8: 106.37958 | EW8: 539.12357 | EX8: 0 | EY8: 21.677391 | EZ8: 43.31756
B9: 3 | C9: 2 | D9: Upstream | E9: Capital goods | F9: 1553.4786 | G9: 0 | H9: 0 | I9: 111.91095 | J9: 14.8567 | K9: 0 | L9: 51.229986 | M9: 0 | N9: 0 | O9: 0 | P9: 0 | Q9: 45.66365 | R9: 0 | S9: 507.487 | T9: -0.33072708 | U9: 4.4703406 | V9: 0 | W9: 0 | X9: 0 | Y9: 31.186604 | Z9: 0 | AA9: 6.5154163 | AB9: 0 | AC9: 1.6114739 | AD9: 3.2767352 | AE9: 0 | AF9: 5.1408419 | AG9: 4.1112729 | AH9: 0 | AI9: 12.383367 | AJ9: 78.79598 | AK9: 0.30146601 | AL9: 0 | AM9: 0 | AN9: 0 | AO9: 0 | AP9: 0 | AQ9: 0 | AR9: 41.698919 | AS9: 0 | AT9: 83.331494 | AU9: 0 | AV9: 29.445283 | AW9: 0 | AX9: 0 | AY9: 0.83262591 | AZ9: 0 | BA9: 0 | BB9: 16.777976 | BC9: 0 | BD9: 1.2276385 | BE9: 0 | BF9: 0 | BG9: 0 | BH9: 17.723702 | BI9: 0 | BJ9: 0 | BK9: 0 | BL9: 0 | BM9: 0 | BN9: 0 | BO9: 0 | BP9: 0 | BQ9: 0 | BR9: 56.484665 | BS9: 0 | BT9: 11.93266 | BU9: 0 | BV9: 0 | BW9: 0 | BX9: 0 | BY9: 0 | BZ9: 0 | CA9: 0 | CB9: 0 | CC9: 0 | CD9: 0 | CE9: 0 | CF9: 0 | CG9: 0 | CH9: 0 | CI9: 0 | CJ9: 0.53402641 | CK9: 33.439403 | CL9: 0.85017718 | CM9: 1.9097377 | CN9: 2.0979692 | CO9: 0 | CP9: 0 | CQ9: 1.2547131 | CR9: 23.138014 | CS9: 1.7315285 | CT9: 7.1332569 | CU9: 1.6876071 | CV9: 0 | CW9: 2.0015319 | CX9: 0 | CY9: 6.9626371 | CZ9: 4.6955047 | DA9: 5.2945124 | DB9: 0 | DC9: 0 | DD9: 0 | DE9: 0 | DF9: 0 | DG9: 0 | DH9: 7.628311 | DI9: 5.6732941 | DJ9: 0 | DK9: 0 | DL9: 0 | DM9: 0 | DN9: 0 | DO9: 0 | DP9: 0 | DQ9: 0 | DR9: 0 | DS9: 17.698712 | DT9: 4.4958019 | DU9: 5.1291505 | DV9: 0 | DW9: 0 | DX9: 0 | DY9: 0 | DZ9: 0 | EA9: 0 | EB9: 0 | EC9: 0 | ED9: 0 | EE9: 0 | EF9: 7.2281303 | EG9: 4.8059626 | EH9: 81.548226 | EI9: 0 | EJ9: 0 | EK9: 0 | EL9: 0 | EM9: 0 | EN9: 0 | EO9: 0 | EP9: 0 | EQ9: 0 | ER9: 129.58086 | ES9: 0 | ET9: 0 | EU9: 58.76436 | EV9: 0 | EW9: 0 | EX9: 0 | EY9: 0 | EZ9: 0.12917942
B10: 3 | C10: 3 | D10: Upstream | E10: Fuel and energy related activities | F10: 1173.4546 | G10: 0 | H10: 0 | I10: 20.147809 | J10: 11.497602 | K10: 0 | L10: 52.708475 | M10: 0.87509056 | N10: 0 | O10: 0 | P10: 0 | Q10: 10.825322 | R10: 0 | S10: 17.980938 | T10: 1.8925014 | U10: 2.2802348 | V10: 0 | W10: 0 | X10: 0 | Y10: 16.679025 | Z10: 0 | AA10: 16.959535 | AB10: 0 | AC10: 0 | AD10: 3.330769 | AE10: 0 | AF10: 15.242216 | AG10: 4.5457921 | AH10: 0 | AI10: 25.139249 | AJ10: 48.308008 | AK10: 3.5377815 | AL10: 0 | AM10: 0 | AN10: 0 | AO10: 2.3081366 | AP10: 0.69107493 | AQ10: 0 | AR10: 1.4876213 | AS10: 0 | AT10: 61.757478 | AU10: 0.083958212 | AV10: 7.7663923 | AW10: 0 | AX10: 1.0329917 | AY10: 0 | AZ10: 0 | BA10: 0.46761522 | BB10: 5.8414445 | BC10: 0 | BD10: 10.342264 | BE10: 0 | BF10: 0 | BG10: 0 | BH10: 16.169308 | BI10: 0 | BJ10: 0 | BK10: 0 | BL10: 0 | BM10: 0 | BN10: 0 | BO10: 0 | BP10: 0 | BQ10: 23.764003 | BR10: 0 | BS10: 0.93129404 | BT10: 3.0878478 | BU10: 0 | BV10: 0 | BW10: 0 | BX10: 0 | BY10: 0 | BZ10: 0 | CA10: 0 | CB10: 0 | CC10: 0 | CD10: 0 | CE10: 2.3936557 | CF10: 0 | CG10: 0 | CH10: 0 | CI10: 15.307488 | CJ10: 9.8394469 | CK10: 26.105047 | CL10: 1.6606382 | CM10: 9.0133631 | CN10: 3.7993671 | CO10: 0 | CP10: 0 | CQ10: 2.9663271 | CR10: 4.4533189 | CS10: 7.9335692 | CT10: 12.756694 | CU10: 4.335 | CV10: 5.371745 | CW10: 1.3303752 | CX10: 1.9821625 | CY10: 4.2983498 | CZ10: 1.4916444 | DA10: 0 | DB10: 2.0314468 | DC10: 1.0845722 | DD10: 1.8326564 | DE10: 2.1457949 | DF10: 0.61596902 | DG10: 1.3781553 | DH10: 14.285473 | DI10: 3.2078688 | DJ10: 0 | DK10: 0 | DL10: 0 | DM10: 10.357517 | DN10: 1.0458397 | DO10: 2.5092683 | DP10: 4.3822657 | DQ10: 6.9538971 | DR10: 5.4852244 | DS10: 26.680909 | DT10: 10.196731 | DU10: 6.1211812 | DV10: 0 | DW10: 0 | DX10: 0 | DY10: 0 | DZ10: 0 | EA10: 0 | EB10: 0 | EC10: 0 | ED10: 0 | EE10: 0.9654654 | EF10: 2.4674499 | EG10: 11.659608 | EH10: 389.04475 | EI10: 0 | EJ10: 0 | EK10: 0 | EL10: 0 | EM10: 0 | EN10: 0 | EO10: 26.7783 | EP10: 0 | EQ10: 0 | ER10: 52.082279 | ES10: 0 | ET10: 12.013993 | EU10: 51.133807 | EV10: 7.3014389 | EW10: 15.916524 | EX10: 1.0562394 | EY10: 0 | EZ10: 0
B11: 3 | C11: 4 | D11: Upstream | E11: Upstream transportation and distribution | F11: 22660.451 | G11: 0 | H11: -90.478019 | I11: 31.37629 | J11: 14.850305 | K11: 0 | L11: 0 | M11: 0.13041779 | N11: -5.1065664 | O11: 0 | P11: 0 | Q11: 299.02956 | R11: 0 | S11: 1143.0719 | T11: 207.10148 | U11: 171.10877 | V11: 0 | W11: 0.46917101 | X11: 0 | Y11: 118.74758 | Z11: 0 | AA11: 292.56538 | AB11: 0 | AC11: 44.479765 | AD11: -21.48079 | AE11: 39.706809 | AF11: 581.23264 | AG11: 88.114966 | AH11: 0 | AI11: 359.08432 | AJ11: 220.7786 | AK11: 16.648945 | AL11: 0 | AM11: 0 | AN11: 0 | AO11: 14.416684 | AP11: 1.5921671 | AQ11: -7.3441107 | AR11: -30.847022 | AS11: 1.982299 | AT11: 2524.2116 | AU11: 20.791649 | AV11: 146.60511 | AW11: 0 | AX11: 26.769158 | AY11: 5.4879901 | AZ11: 0 | BA11: 0 | BB11: 194.7204 | BC11: 0 | BD11: 234.24064 | BE11: 0.34049566 | BF11: 0 | BG11: 0 | BH11: 200.90703 | BI11: 0 | BJ11: 0 | BK11: 0 | BL11: 0 | BM11: 0 | BN11: 39.830195 | BO11: 0 | BP11: 0 | BQ11: 378.78298 | BR11: 477.22284 | BS11: 233.29029 | BT11: 0 | BU11: 0 | BV11: 0 | BW11: 0 | BX11: 0 | BY11: 0 | BZ11: 0 | CA11: 0 | CB11: 0 | CC11: 0 | CD11: 0 | CE11: 1.0874765 | CF11: 0 | CG11: 0 | CH11: 0 | CI11: 17.330687 | CJ11: 80.887472 | CK11: 101.70323 | CL11: 89.622329 | CM11: 27.768451 | CN11: 12.748569 | CO11: 0 | CP11: 0 | CQ11: 329.03549 | CR11: 41.301888 | CS11: 23.783143 | CT11: 267.78547 | CU11: 5.062333 | CV11: 76.740483 | CW11: 66.710585 | CX11: 27.015904 | CY11: 70.877676 | CZ11: 16.790555 | DA11: 18.607326 | DB11: 36.325379 | DC11: 10.488776 | DD11: 7.1807061 | DE11: 13.611451 | DF11: 27.48751 | DG11: 6.9036706 | DH11: 116.61338 | DI11: 0 | DJ11: 0 | DK11: 0 | DL11: 0 | DM11: 319.99392 | DN11: 29.149394 | DO11: 6.0720216 | DP11: 79.237718 | DQ11: 64.201641 | DR11: 24.661065 | DS11: 214.90341 | DT11: 64.262438 | DU11: 0.028066671 | DV11: 96.292976 | DW11: 0 | DX11: 0 | DY11: 0 | DZ11: 0 | EA11: 0 | EB11: 0 | EC11: 0 | ED11: 0 | EE11: 164.91225 | EF11: 120.52513 | EG11: 906.36118 | EH11: 4368.2325 | EI11: 0 | EJ11: 0 | EK11: 0 | EL11: 0 | EM11: 0 | EN11: 0 | EO11: 1874.4859 | EP11: 92.103432 | EQ11: 0 | ER11: 3792.6289 | ES11: 0 | ET11: 193.07284 | EU11: 528.18314 | EV11: 0.30259086 | EW11: 252.93885 | EX11: 0 | EY11: 0 | EZ11: 0
B12: 3 | C12: 5 | D12: Upstream | E12: Waste generated in operations | F12: 398.82427 | G12: 0 | H12: 0 | I12: 22.750954 | J12: 13.959694 | K12: 0 | L12: 42.42619 | M12: 0 | N12: 2.4058523 | O12: 0 | P12: 0 | Q12: 2.3539313 | R12: 0 | S12: 37.282678 | T12: 0 | U12: 0 | V12: 0 | W12: 0 | X12: 0 | Y12: 9.1585668 | Z12: 0 | AA12: 11.364582 | AB12: 0 | AC12: 0 | AD12: 0.77750247 | AE12: 0 | AF12: 0 | AG12: 0 | AH12: 0 | AI12: 0 | AJ12: 21.940782 | AK12: 5.6099703 | AL12: 0 | AM12: 0 | AN12: 0 | AO12: 3.3124936 | AP12: 0 | AQ12: 0 | AR12: 2.784268 | AS12: 0 | AT12: 14.319297 | AU12: 0 | AV12: 0 | AW12: 0 | AX12: 0 | AY12: 2.1777249 | AZ12: 0 | BA12: 0 | BB12: 9.7821939 | BC12: 0 | BD12: 0 | BE12: 0 | BF12: 0 | BG12: 0 | BH12: 0 | BI12: 0 | BJ12: 0 | BK12: 0 | BL12: 0 | BM12: 0 | BN12: 0 | BO12: 0 | BP12: 0 | BQ12: 0 | BR12: 30.196007 | BS12: 0 | BT12: 0 | BU12: 0 | BV12: 0 | BW12: 0 | BX12: 0 | BY12: 0 | BZ12: 0 | CA12: 0 | CB12: 0 | CC12: 0 | CD12: 0 | CE12: 4.9080435 | CF12: 0 | CG12: 0 | CH12: 0 | CI12: 0 | CJ12: 12.233609 | CK12: 21.866854 | CL12: 4.8746888 | CM12: 10.269365 | CN12: 0 | CO12: 0 | CP12: 0 | CQ12: 0 | CR12: 0 | CS12: 0 | CT12: 0 | CU12: 0 | CV12: 0 | CW12: 0 | CX12: 0 | CY12: 0 | CZ12: 0 | DA12: 0 | DB12: 0 | DC12: 6.0202825 | DD12: 0 | DE12: 0 | DF12: 0 | DG12: 3.8247951 | DH12: 37.413942 | DI12: 3.3304257 | DJ12: 0 | DK12: 0 | DL12: 0 | DM12: 6.5717261 | DN12: 5.3735074 | DO12: 0.67108977 | DP12: 3.0279947 | DQ12: 0 | DR12: 0 | DS12: 0 | DT12: 0 | DU12: 0 | DV12: 0 | DW12: 0 | DX12: 0 | DY12: 0 | DZ12: 0 | EA12: 0 | EB12: 0 | EC12: 0 | ED12: 0 | EE12: 0 | EF12: 6.0580801 | EG12: 0 | EH12: 0 | EI12: 0 | EJ12: 0 | EK12: 0 | EL12: 0 | EM12: 0 | EN12: 0 | EO12: 39.77718 | EP12: 0 | EQ12: 0 | ER12: 0 | ES12: 0 | ET12: 0 | EU12: 0 | EV12: 0 | EW12: 0 | EX12: 0 | EY12: 0 | EZ12: 0
B13: 3 | C13: 6 | D13: Upstream | E13: Business travel | F13: 3171.7995 | G13: 0 | H13: 0 | I13: 182.03817 | J13: 18.593791 | K13: 6.3719193 | L13: 116.12869 | M13: 0 | N13: 0.94715128 | O13: 0 | P13: 0 | Q13: 205.69346 | R13: 0 | S13: 161.67129 | T13: 18.542308 | U13: 8.0298688 | V13: 0.26728949 | W13: 0.250462 | X13: 0 | Y13: 75.649873 | Z13: 0 | AA13: 27.395583 | AB13: 1.3436009 | AC13: 1.4194121 | AD13: 2.7908651 | AE13: 5.2680273 | AF13: 25.328374 | AG13: 6.5894705 | AH13: 0 | AI13: 50.988623 | AJ13: 67.551748 | AK13: 2.5595342 | AL13: 0 | AM13: 0 | AN13: 0.32541442 | AO13: 0 | AP13: 0.36370363 | AQ13: 0 | AR13: 39.193546 | AS13: 0 | AT13: 46.621271 | AU13: 4.9167948 | AV13: 38.034751 | AW13: 0 | AX13: 6.7320902 | AY13: 8.2163388 | AZ13: 0 | BA13: 3.364679 | BB13: 21.519197 | BC13: 2.3360251 | BD13: 0 | BE13: 0.49096305 | BF13: 3.3291327 | BG13: 22.253992 | BH13: 84.893073 | BI13: 17.859093 | BJ13: 0.1684982 | BK13: 0.77914491 | BL13: 2.972419 | BM13: 7.1880289 | BN13: 13.443626 | BO13: 0 | BP13: 0 | BQ13: 0 | BR13: 50.660953 | BS13: 0 | BT13: 483.11255 | BU13: 0 | BV13: 0 | BW13: 0 | BX13: 0 | BY13: 0 | BZ13: 0 | CA13: 66.24175 | CB13: -170.78273 | CC13: 45.661697 | CD13: 58.879282 | CE13: 3.5280289 | CF13: 0 | CG13: 0 | CH13: 0 | CI13: 26.375867 | CJ13: 8.9527333 | CK13: 30.405729 | CL13: 0.89100921 | CM13: 9.9880168 | CN13: 5.8018404 | CO13: 0 | CP13: 0 | CQ13: 4.1797785 | CR13: 0.53004081 | CS13: 9.9054023 | CT13: 22.296664 | CU13: 1.9180865 | CV13: 0.7877973 | CW13: 2.8302796 | CX13: 3.4994074 | CY13: 7.9980574 | CZ13: 14.128309 | DA13: 9.7214206 | DB13: 2.6092898 | DC13: 0.0064363776 | DD13: 2.1757817 | DE13: 0.35875143 | DF13: 0.15903472 | DG13: 0.14966712 | DH13: 2.6695285 | DI13: 32.255091 | DJ13: 0 | DK13: 0 | DL13: 0 | DM13: 8.9973258 | DN13: 0.34926922 | DO13: 0.6271524 | DP13: 5.2498626 | DQ13: 4.2171609 | DR13: 0.34964544 | DS13: 33.252598 | DT13: 2.9616279 | DU13: 0.0096527883 | DV13: 5.6390203 | DW13: 10.558769 | DX13: -4.3767844 | DY13: 12.534543 | DZ13: 0 | EA13: 0 | EB13: 1.4787731 | EC13: 1.1221082 | ED13: 0.68825933 | EE13: 24.900217 | EF13: 28.452682 | EG13: 71.452959 | EH13: 188.36428 | EI13: 2.3652053 | EJ13: 0 | EK13: 0 | EL13: 0 | EM13: 0 | EN13: 0 | EO13: 83.626156 | EP13: 0 | EQ13: 67.985097 | ER13: 227.8251 | ES13: 1.2668371 | ET13: 30.475585 | EU13: 257.51728 | EV13: 8.9465241 | EW13: 6.2425632 | EX13: 0 | EY13: -0.76425986 | EZ13: 41.167439
B14: 3 | C14: 7 | D14: Upstream | E14: Employee commuting | F14: 3379.0944 | G14: 0 | H14: 0 | I14: 86.841374 | J14: 36.666358 | K14: 0 | L14: 116.7534 | M14: 0 | N14: 0 | O14: 0 | P14: 0 | Q14: 64.648579 | R14: 0 | S14: 114.8236 | T14: 28.947125 | U14: 22.192796 | V14: 0 | W14: 1.9298083 | X14: 0 | Y14: 47.280304 | Z14: 0 | AA14: 39.561071 | AB14: 0.96490416 | AC14: 0 | AD14: 17.368275 | AE14: 0 | AF14: 69.4731 | AG14: 21.227892 | AH14: 0 | AI14: 42.455783 | AJ14: 68.508195 | AK14: 10.613946 | AL14: 0 | AM14: 0 | AN14: 0.96490416 | AO14: 2.8947125 | AP14: 4.8245208 | AQ14: 0 | AR14: 14.473562 | AS14: 0 | AT14: 233.50681 | AU14: 4.8245208 | AV14: 18.333179 | AW14: 0 | AX14: 12.543754 | AY14: 0 | AZ14: 0 | BA14: 2.8947125 | BB14: 30.876933 | BC14: 0.96490416 | BD14: 100.35003 | BE14: 0 | BF14: 0 | BG14: 0 | BH14: 123.50773 | BI14: 0 | BJ14: 0 | BK14: 0 | BL14: 0 | BM14: 0 | BN14: 0 | BO14: 0 | BP14: 0 | BQ14: 0 | BR14: 182.36689 | BS14: 0 | BT14: 44.385591 | BU14: 0 | BV14: 0 | BW14: 0 | BX14: 0 | BY14: 6.7543291 | BZ14: 0 | CA14: 2.8947125 | CB14: -4.8245208 | CC14: 1.9298083 | CD14: 1.9298083 | CE14: 1.9298083 | CF14: 0 | CG14: 0 | CH14: 0 | CI14: 25.087508 | CJ14: 24.122604 | CK14: 67.543291 | CL14: 11.57885 | CM14: 32.806741 | CN14: 8.6841374 | CO14: 0 | CP14: 0 | CQ14: 55.964441 | CR14: 36.666358 | CS14: 34.73655 | CT14: 102.27984 | CU14: 17.368275 | CV14: 17.368275 | CW14: 19.298083 | CX14: 11.57885 | CY14: 9.6490416 | CZ14: 7.7192333 | DA14: 0 | DB14: 8.6841374 | DC14: 0 | DD14: 4.8245208 | DE14: 10.613946 | DF14: 4.8245208 | DG14: 3.8596166 | DH14: 67.543291 | DI14: 30.876933 | DJ14: 0 | DK14: 0 | DL14: 0 | DM14: 51.139921 | DN14: 7.7192333 | DO14: 8.6841374 | DP14: 20.262987 | DQ14: 28.947125 | DR14: 17.368275 | DS14: 69.4731 | DT14: 20.262987 | DU14: 56.929345 | DV14: 0 | DW14: 0 | DX14: 0 | DY14: 0 | DZ14: 0 | EA14: 0 | EB14: 0 | EC14: 0 | ED14: 0 | EE14: 8.6841374 | EF14: 19.298083 | EG14: 61.753866 | EH14: 306.83952 | EI14: 6.7543291 | EJ14: 0 | EK14: 0.96490416 | EL14: 0 | EM14: 0.96490416 | EN14: 0 | EO14: 109.03417 | EP14: 0 | EQ14: 10.613946 | ER14: 185.2616 | ES14: 0 | ET14: 34.73655 | EU14: 131.22697 | EV14: 3.8596166 | EW14: 22.192796 | EX14: 0 | EY14: 0 | EZ14: 3.8596166
B15: 3 | C15: 8 | D15: Upstream | E15: Upstream leased assets | F15: 1436.436 | G15: 0 | H15: 0 | I15: 23.437325 | J15: 14.379551 | K15: 0 | L15: 40.872918 | M15: 1.0702224 | N15: 1.6219169 | O15: 0 | P15: 0 | Q15: 10.04183 | R15: 0 | S15: 58.744947 | T15: 12.411337 | U15: 15.136777 | V15: 1.6429786 | W15: 0.91379378 | X15: 0 | Y15: 13.086631 | Z15: 0 | AA15: 41.348205 | AB15: 0 | AC15: 3.8302778 | AD15: 2.9295296 | AE15: 0.57411038 | AF15: 31.515103 | AG15: 4.6853484 | AH15: 0 | AI15: 5.3540884 | AJ15: 14.844576 | AK15: 4.1437688 | AL15: 0 | AM15: 0 | AN15: 0 | AO15: 2.5244423 | AP15: 5.9332223 | AQ15: 0 | AR15: 4.3374907 | AS15: 0 | AT15: 47.595315 | AU15: 0.52295857 | AV15: 13.67145 | AW15: 0 | AX15: 1.7445952 | AY15: 6.8725178 | AZ15: 0 | BA15: 1.0334105 | BB15: 9.6379626 | BC15: 0 | BD15: 4.0368435 | BE15: 3.6002592 | BF15: 1.1555744 | BG15: 9.2908661 | BH15: 30.273803 | BI15: 0 | BJ15: 0 | BK15: 0 | BL15: 0 | BM15: 0 | BN15: 0 | BO15: 0 | BP15: 0 | BQ15: 0 | BR15: 79.597276 | BS15: 0 | BT15: 30.243062 | BU15: 0 | BV15: 0 | BW15: 0 | BX15: 0 | BY15: 0 | BZ15: 0 | CA15: 0 | CB15: 0 | CC15: 0 | CD15: 0 | CE15: 1.2276399 | CF15: 0 | CG15: 0 | CH15: 0 | CI15: 5.4686493 | CJ15: 7.5479624 | CK15: 29.890529 | CL15: 4.6276777 | CM15: 10.428291 | CN15: 1.6341155 | CO15: 0 | CP15: 0 | CQ15: 21.086228 | CR15: 9.0175263 | CS15: 7.764375 | CT15: 33.612607 | CU15: 0.92615709 | CV15: 1.1764301 | CW15: 3.5874619 | CX15: 3.8370325 | CY15: 10.423483 | CZ15: 0.54752516 | DA15: 3.7802002 | DB15: 3.4060575 | DC15: 0.8032104 | DD15: 2.0664121 | DE15: 6.4302294 | DF15: 1.8341631 | DG15: 1.2373836 | DH15: 0 | DI15: 1.9613609 | DJ15: -6.1336067 | DK15: 0 | DL15: 0 | DM15: 16.821932 | DN15: 1.5752343 | DO15: 4.702093 | DP15: 8.0010592 | DQ15: 5.482279 | DR15: 4.1097694 | DS15: 20.756023 | DT15: 4.7908363 | DU15: 1.8647041 | DV15: 15.324812 | DW15: 0 | DX15: 0 | DY15: 0 | DZ15: 0 | EA15: 3.5434651 | EB15: 2.5636428 | EC15: 2.2823881 | ED15: 0 | EE15: 2.0748982 | EF15: 10.659286 | EG15: 0 | EH15: 362.20617 | EI15: 0 | EJ15: 0 | EK15: 0 | EL15: 0 | EM15: 0 | EN15: 0 | EO15: 72.974325 | EP15: 0 | EQ15: 0 | ER15: 65.648533 | ES15: 0 | ET15: 23.544192 | EU15: 59.159038 | EV15: 10.184911 | EW15: 15.2867 | EX15: 0 | EY15: 0 | EZ15: 0.034310991
B16: 3 | C16: 9 | D16: Downstream | E16: Downstream transportation and distribution | F16: 0 | G16: 0 | H16: 0 | I16: 0 | J16: 0 | K16: 0 | L16: 0 | M16: 0 | N16: 0 | O16: 0 | P16: 0 | Q16: 0 | R16: 0 | S16: 0 | T16: 0 | U16: 0 | V16: 0 | W16: 0 | X16: 0 | Y16: 0 | Z16: 0 | AA16: 0 | AB16: 0 | AC16: 0 | AD16: 0 | AE16: 0 | AF16: 0 | AG16: 0 | AH16: 0 | AI16: 0 | AJ16: 0 | AK16: 0 | AL16: 0 | AM16: 0 | AN16: 0 | AO16: 0 | AP16: 0 | AQ16: 0 | AR16: 0 | AS16: 0 | AT16: 0 | AU16: 0 | AV16: 0 | AW16: 0 | AX16: 0 | AY16: 0 | AZ16: 0 | BA16: 0 | BB16: 0 | BC16: 0 | BD16: 0 | BE16: 0 | BF16: 0 | BG16: 0 | BH16: 0 | BI16: 0 | BJ16: 0 | BK16: 0 | BL16: 0 | BM16: 0 | BN16: 0 | BO16: 0 | BP16: 0 | BQ16: 0 | BR16: 0 | BS16: 0 | BT16: 0 | BU16: 0 | BV16: 0 | BW16: 0 | BX16: 0 | BY16: 0 | BZ16: 0 | CA16: 0 | CB16: 0 | CC16: 0 | CD16: 0 | CE16: 0 | CF16: 0 | CG16: 0 | CH16: 0 | CI16: 0 | CJ16: 0 | CK16: 0 | CL16: 0 | CM16: 0 | CN16: 0 | CO16: 0 | CP16: 0 | CQ16: 0 | CR16: 0 | CS16: 0 | CT16: 0 | CU16: 0 | CV16: 0 | CW16: 0 | CX16: 0 | CY16: 0 | CZ16: 0 | DA16: 0 | DB16: 0 | DC16: 0 | DD16: 0 | DE16: 0 | DF16: 0 | DG16: 0 | DH16: 0 | DI16: 0 | DJ16: 0 | DK16: 0 | DL16: 0 | DM16: 0 | DN16: 0 | DO16: 0 | DP16: 0 | DQ16: 0 | DR16: 0 | DS16: 0 | DT16: 0 | DU16: 0 | DV16: 0 | DW16: 0 | DX16: 0 | DY16: 0 | DZ16: 0 | EA16: 0 | EB16: 0 | EC16: 0 | ED16: 0 | EE16: 0 | EF16: 0 | EG16: 0 | EH16: 0 | EI16: 0 | EJ16: 0 | EK16: 0 | EL16: 0 | EM16: 0 | EN16: 0 | EO16: 0 | EP16: 0 | EQ16: 0 | ER16: 0 | ES16: 0 | ET16: 0 | EU16: 0 | EV16: 0 | EW16: 0 | EX16: 0 | EY16: 0 | EZ16: 0
B17: 3 | C17: 10 | D17: Downstream | E17: Processing of sold products | F17: 0 | G17: 0 | H17: 0 | I17: 0 | J17: 0 | K17: 0 | L17: 0 | M17: 0 | N17: 0 | O17: 0 | P17: 0 | Q17: 0 | R17: 0 | S17: 0 | T17: 0 | U17: 0 | V17: 0 | W17: 0 | X17: 0 | Y17: 0 | Z17: 0 | AA17: 0 | AB17: 0 | AC17: 0 | AD17: 0 | AE17: 0 | AF17: 0 | AG17: 0 | AH17: 0 | AI17: 0 | AJ17: 0 | AK17: 0 | AL17: 0 | AM17: 0 | AN17: 0 | AO17: 0 | AP17: 0 | AQ17: 0 | AR17: 0 | AS17: 0 | AT17: 0 | AU17: 0 | AV17: 0 | AW17: 0 | AX17: 0 | AY17: 0 | AZ17: 0 | BA17: 0 | BB17: 0 | BC17: 0 | BD17: 0 | BE17: 0 | BF17: 0 | BG17: 0 | BH17: 0 | BI17: 0 | BJ17: 0 | BK17: 0 | BL17: 0 | BM17: 0 | BN17: 0 | BO17: 0 | BP17: 0 | BQ17: 0 | BR17: 0 | BS17: 0 | BT17: 0 | BU17: 0 | BV17: 0 | BW17: 0 | BX17: 0 | BY17: 0 | BZ17: 0 | CA17: 0 | CB17: 0 | CC17: 0 | CD17: 0 | CE17: 0 | CF17: 0 | CG17: 0 | CH17: 0 | CI17: 0 | CJ17: 0 | CK17: 0 | CL17: 0 | CM17: 0 | CN17: 0 | CO17: 0 | CP17: 0 | CQ17: 0 | CR17: 0 | CS17: 0 | CT17: 0 | CU17: 0 | CV17: 0 | CW17: 0 | CX17: 0 | CY17: 0 | CZ17: 0 | DA17: 0 | DB17: 0 | DC17: 0 | DD17: 0 | DE17: 0 | DF17: 0 | DG17: 0 | DH17: 0 | DI17: 0 | DJ17: 0 | DK17: 0 | DL17: 0 | DM17: 0 | DN17: 0 | DO17: 0 | DP17: 0 | DQ17: 0 | DR17: 0 | DS17: 0 | DT17: 0 | DU17: 0 | DV17: 0 | DW17: 0 | DX17: 0 | DY17: 0 | DZ17: 0 | EA17: 0 | EB17: 0 | EC17: 0 | ED17: 0 | EE17: 0 | EF17: 0 | EG17: 0 | EH17: 0 | EI17: 0 | EJ17: 0 | EK17: 0 | EL17: 0 | EM17: 0 | EN17: 0 | EO17: 0 | EP17: 0 | EQ17: 0 | ER17: 0 | ES17: 0 | ET17: 0 | EU17: 0 | EV17: 0 | EW17: 0 | EX17: 0 | EY17: 0 | EZ17: 0
B18: 3 | C18: 11 | D18: Downstream | E18: Use of sold products | F18: 861.11502 | G18: 0 | H18: 0 | I18: 418.42447 | J18: 0 | K18: 0 | L18: 0 | M18: 0 | N18: 0 | O18: 0 | P18: 0 | Q18: 237.41245 | R18: 0 | S18: 0 | T18: 0 | U18: 0 | V18: 0 | W18: 0 | X18: 0 | Y18: 0 | Z18: 0 | AA18: 0 | AB18: 0 | AC18: 0 | AD18: 0 | AE18: 0 | AF18: 0 | AG18: 0 | AH18: 0 | AI18: 0 | AJ18: 0 | AK18: 0 | AL18: 0 | AM18: 0 | AN18: 0 | AO18: 0 | AP18: 0 | AQ18: 0 | AR18: 205.27811 | AS18: 0 | AT18: 0 | AU18: 0 | AV18: 0 | AW18: 0 | AX18: 0 | AY18: 0 | AZ18: 0 | BA18: 0 | BB18: 0 | BC18: 0 | BD18: 0 | BE18: 0 | BF18: 0 | BG18: 0 | BH18: 0 | BI18: 0 | BJ18: 0 | BK18: 0 | BL18: 0 | BM18: 0 | BN18: 0 | BO18: 0 | BP18: 0 | BQ18: 0 | BR18: 0 | BS18: 0 | BT18: 0 | BU18: 0 | BV18: 0 | BW18: 0 | BX18: 0 | BY18: 0 | BZ18: 0 | CA18: 0 | CB18: 0 | CC18: 0 | CD18: 0 | CE18: 0 | CF18: 0 | CG18: 0 | CH18: 0 | CI18: 0 | CJ18: 0 | CK18: 0 | CL18: 0 | CM18: 0 | CN18: 0 | CO18: 0 | CP18: 0 | CQ18: 0 | CR18: 0 | CS18: 0 | CT18: 0 | CU18: 0 | CV18: 0 | CW18: 0 | CX18: 0 | CY18: 0 | CZ18: 0 | DA18: 0 | DB18: 0 | DC18: 0 | DD18: 0 | DE18: 0 | DF18: 0 | DG18: 0 | DH18: 0 | DI18: 0 | DJ18: 0 | DK18: 0 | DL18: 0 | DM18: 0 | DN18: 0 | DO18: 0 | DP18: 0 | DQ18: 0 | DR18: 0 | DS18: 0 | DT18: 0 | DU18: 0 | DV18: 0 | DW18: 0 | DX18: 0 | DY18: 0 | DZ18: 0 | EA18: 0 | EB18: 0 | EC18: 0 | ED18: 0 | EE18: 0 | EF18: 0 | EG18: 0 | EH18: 0 | EI18: 0 | EJ18: 0 | EK18: 0 | EL18: 0 | EM18: 0 | EN18: 0 | EO18: 0 | EP18: 0 | EQ18: 0 | ER18: 0 | ES18: 0 | ET18: 0 | EU18: 0 | EV18: 0 | EW18: 0 | EX18: 0 | EY18: 0 | EZ18: 0
B19: 3 | C19: 12 | D19: Downstream | E19: End of life treatment of sold products | F19: 20.476429 | G19: 0 | H19: 0.017645739 | I19: 0.27349999 | J19: 0.016436531 | K19: 0 | L19: 0 | M19: 0.00032415285 | N19: 0.0044751005 | O19: 0 | P19: 0 | Q19: 0.34248743 | R19: 0 | S19: 0.74772242 | T19: 0.15942786 | U19: 0.093362117 | V19: 0 | W19: 0.0011661225 | X19: 0 | Y19: 0.28307137 | Z19: 0 | AA19: 0.16713003 | AB19: 0 | AC19: 0.026432254 | AD19: 0.019780292 | AE19: 0.092102775 | AF19: 0.46018525 | AG19: 0.03053028 | AH19: 0 | AI19: 0.27023752 | AJ19: 0.14706438 | AK19: 0.023187657 | AL19: 0 | AM19: 0 | AN19: 0 | AO19: 0.025958863 | AP19: 0 | AQ19: 0.011532157 | AR19: 0.024567655 | AS19: 0.0032449338 | AT19: 1.913999 | AU19: 0.02321387 | AV19: 0.085896104 | AW19: 0 | AX19: 0.027579128 | AY19: 0.035325623 | AZ19: 0 | BA19: 0 | BB19: 0.21773548 | BC19: 0 | BD19: 0.52664249 | BE19: 0.00089595383 | BF19: 0 | BG19: 0 | BH19: 0.40070767 | BI19: 0 | BJ19: 0 | BK19: 0 | BL19: 0 | BM19: 0 | BN19: 0.067741116 | BO19: 0 | BP19: 0 | BQ19: 0.74598778 | BR19: 0.3689986 | BS19: 0.24843304 | BT19: 0 | BU19: 0 | BV19: 0 | BW19: 0 | BX19: 0 | BY19: 0 | BZ19: 0 | CA19: 0 | CB19: 0 | CC19: 0 | CD19: 0 | CE19: 0 | CF19: 0 | CG19: 0 | CH19: 0 | CI19: 0 | CJ19: 0 | CK19: 0.028241343 | CL19: 0 | CM19: 0 | CN19: 0.0093305046 | CO19: 0 | CP19: 0 | CQ19: 0 | CR19: 0 | CS19: 0 | CT19: 0.18514747 | CU19: 0 | CV19: 0 | CW19: 0.00013331324 | CX19: 0.016327926 | CY19: 0 | CZ19: 0 | DA19: 0 | DB19: 0 | DC19: 0.0092385947 | DD19: 0.001141885 | DE19: 0 | DF19: 0 | DG19: 0.0054560157 | DH19: 0.21173794 | DI19: 0 | DJ19: 0 | DK19: 0 | DL19: 0 | DM19: 0.27596518 | DN19: 0.020375798 | DO19: 0.0033722409 | DP19: 0.052748569 | DQ19: 0 | DR19: 0 | DS19: 0 | DT19: 0 | DU19: 0 | DV19: 0.19112163 | DW19: 0 | DX19: 0 | DY19: 0 | DZ19: 0 | EA19: 0 | EB19: 0 | EC19: 0 | ED19: 0 | EE19: 0.011786578 | EF19: 0.092123557 | EG19: 0 | EH19: 7.2158518 | EI19: 0 | EJ19: 0 | EK19: 0 | EL19: 0 | EM19: 0 | EN19: 0 | EO19: 0.12350719 | EP19: 0.022541482 | EQ19: 0 | ER19: 3.4188551 | ES19: 0 | ET19: 0.31132118 | EU19: 0.36537521 | EV19: 0 | EW19: 0 | EX19: 0 | EY19: 0 | EZ19: 0
... B22: 3 | C22: 15 | D22: Downstream | E22: Investments | F22: 0 | G22: 0 | H22: 0 | I22: 0 | J22: 0 | K22: 0 | L22: 0 | M22: 0 | N22: 0 | O22: 0 | P22: 0 | Q22: 0 | R22: 0 | S22: 0 | T22: 0 | U22: 0 | V22: 0 | W22: 0 | X22: 0 | Y22: 0 | Z22: 0 | AA22: 0 | AB22: 0 | AC22: 0 | AD22: 0 | AE22: 0 | AF22: 0 | AG22: 0 | AH22: 0 | AI22: 0 | AJ22: 0 | AK22: 0 | AL22: 0 | AM22: 0 | AN22: 0 | AO22: 0 | AP22: 0 | AQ22: 0 | AR22: 0 | AS22: 0 | AT22: 0 | AU22: 0 | AV22: 0 | AW22: 0 | AX22: 0 | AY22: 0 | AZ22: 0 | BA22: 0 | BB22: 0 | BC22: 0 | BD22: 0 | BE22: 0 | BF22: 0 | BG22: 0 | BH22: 0 | BI22: 0 | BJ22: 0 | BK22: 0 | BL22: 0 | BM22: 0 | BN22: 0 | BO22: 0 | BP22: 0 | BQ22: 0 | BR22: 0 | BS22: 0 | BT22: 0 | BU22: 0 | BV22: 0 | BW22: 0 | BX22: 0 | BY22: 0 | BZ22: 0 | CA22: 0 | CB22: 0 | CC22: 0 | CD22: 0 | CE22: 0 | CF22: 0 | CG22: 0 | CH22: 0 | CI22: 0 | CJ22: 0 | CK22: 0 | CL22: 0 | CM22: 0 | CN22: 0 | CO22: 0 | CP22: 0 | CQ22: 0 | CR22: 0 | CS22: 0 | CT22: 0 | CU22: 0 | CV22: 0 | CW22: 0 | CX22: 0 | CY22: 0 | CZ22: 0 | DA22: 0 | DB22: 0 | DC22: 0 | DD22: 0 | DE22: 0 | DF22: 0 | DG22: 0 | DH22: 0 | DI22: 0 | DJ22: 0 | DK22: 0 | DL22: 0 | DM22: 0 | DN22: 0 | DO22: 0 | DP22: 0 | DQ22: 0 | DR22: 0 | DS22: 0 | DT22: 0 | DU22: 0 | DV22: 0 | DW22: 0 | DX22: 0 | DY22: 0 | DZ22: 0 | EA22: 0 | EB22: 0 | EC22: 0 | ED22: 0 | EE22: 0 | EF22: 0 | EG22: 0 | EH22: 0 | EI22: 0 | EJ22: 0 | EK22: 0 | EL22: 0 | EM22: 0 | EN22: 0 | EO22: 0 | EP22: 0 | EQ22: 0 | ER22: 0 | ES22: 0 | ET22: 0 | EU22: 0 | EV22: 0 | EW22: 0 | EX22: 0 | EY22: 0 | EZ22: 0
E23: Total LB | F23: 119158.19 | G23: 0.8714176 | H23: 765.68387 | I23: 4801.8 | J23: 751.09079 | K23: -3.9444069 | L23: 1935.8916 | M23: 6.696795 | N23: 65.158064 | O23: 0 | P23: 0 | Q23: 4930.0055 | R23: 0 | S23: 8254.1127 | T23: 763.76977 | U23: 855.87144 | V23: 1.992886 | W23: 9.2539648 | X23: -57.844455 | Y23: 2270.2716 | Z23: 0 | AA23: 920.22427 | AB23: 3.2556637 | AC23: 95.432208 | AD23: 248.20057 | AE23: 183.04224 | AF23: 1876.7403 | AG23: 1161.5231 | AH23: 2.0094466 | AI23: 3104.481 | AJ23: 4007.4226 | AK23: 594.68132 | AL23: 116.19232 | AM23: 0 | AN23: 2.7652732 | AO23: 93.397569 | AP23: 53.430224 | AQ23: 179.67979 | AR23: 811.84205 | AS23: 98.063117 | AT23: 5394.8148 | AU23: 191.29286 | AV23: 1721.8194 | AW23: 0 | AX23: 313.59576 | AY23: 150.59831 | AZ23: 0 | BA23: 11.284582 | BB23: 1125.1949 | BC23: 3.8120209 | BD23: 1509.4068 | BE23: -16.09549 | BF23: 19.279776 | BG23: 98.803169 | BH23: 2040.0037 | BI23: 20.578679 | BJ23: 3.0722256 | BK23: 1.016279 | BL23: 4.7213537 | BM23: 8.4942802 | BN23: 443.37301 | BO23: 0 | BP23: 0 | BQ23: 932.5367 | BR23: 1957.4155 | BS23: 657.54603 | BT23: 1406.6791 | BU23: 0 | BV23: 0.058196984 | BW23: 0.014047579 | BX23: 0.63661389 | BY23: 6.7543291 | BZ23: 2464.2223 | CA23: 503.67036 | CB23: -182.31914 | CC23: 47.731905 | CD23: -116.874 | CE23: 374.38029 | CF23: 0 | CG23: 0 | CH23: 0 | CI23: 312.34446 | CJ23: 383.01048 | CK23: 938.52136 | CL23: 245.38029 | CM23: 322.41655 | CN23: 146.97126 | CO23: 0 | CP23: 0 | CQ23: 828.77523 | CR23: 511.52073 | CS23: 329.00807 | CT23: 1058.3869 | CU23: 33.646564 | CV23: 232.08722 | CW23: 293.58926 | CX23: 141.099 | CY23: 500.65957 | CZ23: 80.980283 | DA23: 223.3548 | DB23: 128.70385 | DC23: 40.673407 | DD23: 60.174587 | DE23: 123.55878 | DF23: 97.701916 | DG23: 68.38884 | DH23: 1016.1086 | DI23: 165.23888 | DJ23: -5.8118498 | DK23: 0 | DL23: 0 | DM23: 724.27633 | DN23: 81.756014 | DO23: 66.497918 | DP23: 348.36852 | DQ23: 222.2552 | DR23: 443.16469 | DS23: 1174.5632 | DT23: 385.35694 | DU23: 1091.8223 | DV23: 765.92452 | DW23: 28.684052 | DX23: -1.800443 | DY23: 28.085429 | DZ23: 2.6657774 | EA23: 10.279806 | EB23: 34.926693 | EC23: 10.889677 | ED23: 2.0464742 | EE23: 431.85603 | EF23: 842.11216 | EG23: 3880.5902 | EH23: 7965.28 | EI23: 92.218992 | EJ23: 220.26643 | EK23: -159.95689 | EL23: -53.591333 | EM23: 0.96490416 | EN23: 0 | EO23: 11161.036 | EP23: 184.9399 | EQ23: 173.45297 | ER23: 10721.772 | ES23: 4.2260243 | ET23: 852.14223 | EU23: 7939.3565 | EV23: 185.25968 | EW23: 904.80777 | EX23: 5.2008623 | EY23: 20.913131 | EZ23: 88.508107
E24: Total MB | F24: 119766.32 | G24: 0.8714176 | H24: 765.68387 | I24: 4801.8 | J24: 751.09079 | K24: -3.9444069 | L24: 1935.8916 | M24: 6.696795 | N24: 65.158064 | O24: 0 | P24: 0 | Q24: 4930.0055 | R24: 0 | S24: 8254.1127 | T24: 763.76977 | U24: 855.87144 | V24: 1.992886 | W24: 9.2539648 | X24: -57.844455 | Y24: 2288.6125 | Z24: 0 | AA24: 962.13086 | AB24: 3.2556637 | AC24: 95.432208 | AD24: 255.8276 | AE24: 183.04224 | AF24: 1892.1224 | AG24: 1168.2543 | AH24: 2.0094466 | AI24: 3121.5781 | AJ24: 4019.9734 | AK24: 596.43317 | AL24: 116.19232 | AM24: 0 | AN24: 2.7652732 | AO24: 94.622255 | AP24: 53.093165 | AQ24: 179.67979 | AR24: 811.84205 | AS24: 98.063117 | AT24: 5496.5131 | AU24: 191.65724 | AV24: 1724.4872 | AW24: 0 | AX24: 313.8584 | AY24: 150.59831 | AZ24: 0 | BA24: 11.284582 | BB24: 1136.0216 | BC24: 3.8120209 | BD24: 1523.4658 | BE24: -16.09549 | BF24: 19.279776 | BG24: 98.803169 | BH24: 2072.0094 | BI24: 20.578679 | BJ24: 3.0722256 | BK24: 1.016279 | BL24: 4.7213537 | BM24: 8.4942802 | BN24: 443.37301 | BO24: 0 | BP24: 0 | BQ24: 992.03705 | BR24: 1957.4155 | BS24: 659.33722 | BT24: 1414.6913 | BU24: 0 | BV24: 0.058196984 | BW24: 0.014047579 | BX24: 0.63661389 | BY24: 6.7543291 | BZ24: 2464.2223 | CA24: 503.67036 | CB24: -182.31914 | CC24: 47.731905 | CD24: -116.874 | CE24: 374.38029 | CF24: 0 | CG24: 0 | CH24: 0 | CI24: 318.48081 | CJ24: 388.22694 | CK24: 947.17247 | CL24: 247.09578 | CM24: 329.76696 | CN24: 148.70435 | CO24: 0 | CP24: 0 | CQ24: 835.43426 | CR24: 515.49674 | CS24: 330.89067 | CT24: 1077.7594 | CU24: 44.014942 | CV24: 240.52307 | CW24: 295.34002 | CX24: 142.713 | CY24: 502.36902 | CZ24: 84.85075 | DA24: 223.3548 | DB24: 130.2178 | DC24: 43.436432 | DD24: 61.384457 | DE24: 125.50856 | DF24: 99.300211 | DG24: 69.59871 | DH24: 1034.0623 | DI24: 165.64615 | DJ24: -5.8118498 | DK24: 0 | DL24: 0 | DM24: 743.14497 | DN24: 84.4669 | DO24: 68.452647 | DP24: 354.87895 | DQ24: 234.94689 | DR24: 443.59148 | DS24: 1174.0602 | DT24: 386.38166 | DU24: 1093.3176 | DV24: 765.92452 | DW24: 28.684052 | DX24: -1.800443 | DY24: 28.085429 | DZ24: 2.6657774 | EA24: 10.279806 | EB24: 34.926693 | EC24: 10.889677 | ED24: 2.0464742 | EE24: 431.91168 | EF24: 842.25689 | EG24: 3880.905 | EH24: 8023.8493 | EI24: 92.218992 | EJ24: 220.26643 | EK24: -159.95689 | EL24: -53.591333 | EM24: 0.96490416 | EN24: 0 | EO24: 11165.479 | EP24: 184.9399 | EQ24: 173.45297 | ER24: 10722.59 | ES24: 4.2260243 | ET24: 853.97633 | EU24: 7960.1367 | EV24: 187.24453 | EW24: 905.27482 | EX24: 6.2308867 | EY24: 20.913131 | EZ24: 88.508107
B26: FY25 Summary (H1)
B28: Scope | C28: Category | D28: Upstream/Downstream | E28: Emission Source | F28: tCO2e Market | G28: tCO2e Location
B29: 1 | C29: - | D29: Internal | E29: Stationary combustion | F29: 1336.419 | G29: 1336.419
B30: 1 | C30: - | D30: Internal | E30: Company vehicles | F30: 936.81688 | G30: 936.81688
B31: 1 | C31: - | D31: Internal | E31: Fugitive emissions | F31: 0 | G31: 0
B32: 1 | C32: - | D32: Internal | E32: Refrigerants | F32: 6.410566 | G32: 6.410566
B33: 1 | C33: - | D33: Internal | E33: Extrapolated tCo2e | F33: 0 | G33: 0
B34: 2 | C34: - | D34: Internal | E34: Electricity usage | F34: 3365.3929 | G34: 2757.2595
B35: 2 | C35: - | D35: Internal | E35: Heating | F35: 53.952952 | G35: 53.952952
B36: 2 | C36: - | D36: Internal | E36: Cooling | F36: 0 | G36: 0
B37: 2 | C37: - | D37: Internal | E37: Extrapolated tCo2e | F37: 0 | G37: 0
B38: 3 | C38: 1 | D38: Upstream | E38: Purchased goods and services | F38: 79412.202 | G38: 79412.202
B39: 3 | C39: 2 | D39: Upstream | E39: Capital goods | F39: 1553.4786 | G39: 1553.4786
B40: 3 | C40: 3 | D40: Upstream | E40: Fuel and energy related activities | F40: 1173.4546 | G40: 1173.4546
B41: 3 | C41: 4 | D41: Upstream | E41: Upstream transportation and distribution | F41: 22660.451 | G41: 22660.451
B42: 3 | C42: 5 | D42: Upstream | E42: Waste generated in operations | F42: 398.82427 | G42: 398.82427
B43: 3 | C43: 6 | D43: Upstream | E43: Business travel | F43: 3171.7995 | G43: 3171.7995
B44: 3 | C44: 7 | D44: Upstream | E44: Employee commuting | F44: 3379.0944 | G44: 3379.0944
B45: 3 | C45: 8 | D45: Upstream | E45: Upstream leased assets | F45: 1436.436 | G45: 1436.436
B46: 3 | C46: 9 | D46: Downstream | E46: Downstream transportation and distribution | F46: 0 | G46: 0
...

Sheet FY24
B2: FY24 Footprint by Entity Code
BO3: Divested | BP3: Divested
B4: Scope | C4: Category | D4: Upstream/Downstream | E4: Emission Source | F4: Diploma Total | G4: G3010 | H4: L2050 | I4: L3015 | J4: S7030 | K4: S7040 | L4: S7060 | M4: S7090 | N4: S6040 | O4: G5020 | P4: L2010 | Q4: L2020 | R4: L2030 | S4: L2040 | T4: S2050 | U4: S2060 | V4: C5520 | W4: S4030 | X4: G5040 | Y4: L2500 | Z4: L7010 | AA4: S4010 | AB4: C2540 | AC4: C4050 | AD4: C2090 | AE4: C2091 | AF4: c4030 | AG4: C7010 | AH4: G3045 | AI4: L2090 | AJ4: L5010 | AK4: S1030 | AL4: G5025 | AM4: HoIntSealsE | AN4: S1040 | AO4: S2210 | AP4: S7020 | AQ4: L2060 | AR4: L3025 | AS4: L7030 | AT4: S1010 | AU4: L2510 | AV4: L2700 | AW4: L7020 | AX4: S4020 | AY4: S6020 | AZ4: S6070 | BA4: C2530 | BB4: c1010 | BC4: C1040 | BD4: C2040 | BE4: C2041 | BF4: C2042 | BG4: C2043 | BH4: C2080 | BI4: C2551 | BJ4: C2552 | BK4: C2553 | BL4: C2554 | BM4: C2555 | BN4: C3510 | BO4: C5010 | BP4: C6020 | BQ4: C8010 | BR4: C9010 | BS4: C9050 | BT4: G2010 | BU4: G3015 | BV4: G3020 | BW4: G3041 | BX4: G4010 | BY4: G5005 | BZ4: G5010 | CA4: HoControls | CB4: HoGrp | CC4: HoIntSeals | CD4: HoLS | CE4: L5020 | CF4: R1100 | CG4: R1120 | CH4: R1140 | CI4: R1170 | CJ4: R1180 | CK4: R1190 | CL4: R1210 | CM4: R1220 | CN4: R1230 | CO4: R1240 | CP4: R2100 | CQ4: R2110 | CR4: R2120 | CS4: R2130 | CT4: R2150 | CU4: R2160 | CV4: R2170 | CW4: R2180 | CX4: R2190 | CY4: R2210 | CZ4: R2220 | DA4: R3100 | DB4: R4100 | DC4: R4110 | DD4: R4120 | DE4: R4130 | DF4: R4140 | DG4: R4150 | DH4: R4160 | DI4: R5100 | DJ4: R5110 | DK4: R5120 | DL4: R9100 | DM4: S3010 | DN4: S3030 | DO4: S4040 | DP4: S4050 | DQ4: S9010 | DR4: C1510 | DS4: C1520 | DT4: C1530 | DU4: C2045 | DV4: C2046 | DW4: C2571 | DX4: C2572 | DY4: C2573 | DZ4: C2574 | EA4: C2575 | EB4: C2576 | EC4: C2577 | ED4: C2578 | EE4: C3040 | EF4: C4510 | EG4: C5510 | EH4: C8500 | EI4: G3025 | EJ4: G5015 | EK4: HoControlsU | EL4: HoDHI | EM4: HoLSU | EN4: HoNaSeals | EO4: LCAoem | EP4: S1020 | EQ4: S2010 | ER4: S2025 | ES4: S2026 | ET4: S2310 | EU4: S8010 | EV4: S8020 | EW4: S8030
B5: 1 | C5: - | D5: Internal | E5: All Scope 1 | F5: 3875.1797 | G5: 0 | H5: 0 | I5: 0.603811 | J5: 31.250352 | K5: 0 | L5: 359.71836 | M5: 0 | N5: 16.293485 | O5: 0 | P5: 0 | Q5: 61.688106 | R5: 67.284091 | S5: 57.991748 | T5: 1.7636592 | U5: 0.23839808 | V5: 0 | W5: 0 | X5: 0 | Y5: 69.583192 | Z5: 0 | AA5: 47.56803 | AB5: 0 | AC5: 41.879823 | AD5: 19.794807 | AE5: 0 | AF5: 77.90626 | AG5: 22.504836 | AH5: 0 | AI5: 86.711815 | AJ5: 387.94081 | AK5: 15.857309 | AL5: 0 | AM5: 0 | AN5: 0 | AO5: 10.317098 | AP5: 2.8020755 | AQ5: 0 | AR5: 8.2696834 | AS5: 0 | AT5: 60.870391 | AU5: 3.7419149 | AV5: 27.955154 | AW5: 0 | AX5: 12.958316 | AY5: 25.703715 | AZ5: 0 | BA5: 0 | BB5: 12.826717 | BC5: 0 | BD5: 35.470791 | BE5: 0 | BF5: 0 | BG5: 0 | BH5: 65.968327 | BI5: 0 | BJ5: 0 | BK5: 0 | BL5: 0 | BM5: 0 | BN5: 0 | BO5: 0 | BP5: 0 | BQ5: 10.844279 | BR5: 2.0692019 | BS5: 10.030795 | BT5: 0 | BU5: 0 | BV5: 0 | BW5: 0 | BX5: 0 | BY5: 0 | BZ5: 0 | CA5: 0 | CB5: 0 | CC5: 0 | CD5: 0 | CE5: 50.127875 | CF5: 9.1817347 | CG5: 0.84429744 | CH5: 3.2942677 | CI5: 116.67087 | CJ5: 58.568671 | CK5: 121.04779 | CL5: 6.4973492 | CM5: 53.279166 | CN5: 24.441489 | CO5: 0.77645211 | CP5: 0 | CQ5: 1.1139373 | CR5: 20.93273 | CS5: 75.5578 | CT5: 45.004928 | CU5: 9.4170109 | CV5: 2.1150556 | CW5: 0.60500428 | CX5: 6.0488837 | CY5: 19.532842 | CZ5: 2.298595 | DA5: 299.19743 | DB5: 17.518367 | DC5: 1.834125 | DD5: 10.61409 | DE5: 19.534766 | DF5: 1.2685995 | DG5: 7.9055066 | DH5: 5.4479694 | DI5: 13.976011 | DJ5: 0 | DK5: 0 | DL5: 0 | DM5: 21.213638 | DN5: 1.8687369 | DO5: 9.2364518 | DP5: 9.0207752 | DQ5: 10.318549 | DR5: 32.892946 | DS5: 72.016061 | DT5: 34.394964 | DU5: 1.330162 | DV5: 4.4244245 | DW5: 0 | DX5: 0 | DY5: 0 | DZ5: 0 | EA5: 0 | EB5: 0 | EC5: 0 | ED5: 0 | EE5: 8.7181577 | EF5: 0.42302362 | EG5: 0 | EH5: 584.04009 | EI5: 0 | EJ5: 0 | EK5: 0 | EL5: 0 | EM5: 0 | EN5: 0 | EO5: 85.604518 | EP5: 0 | EQ5: 0 | ER5: 87.557771 | ES5: 0 | ET5: 50.662481 | EU5: 98.309505 | EV5: 17.725172 | EW5: 84.361255
B6: 2 | C6: - | D6: Internal | E6: All Scope 2 MB | F6: 3806.853 | G6: 0 | H6: 0 | I6: 95.811883 | J6: 17.267135 | K6: 0 | L6: 96.247731 | M6: 8.466403 | N6: 25.573495 | O6: 0 | P6: 0 | Q6: 19.604748 | R6: 10.041526 | S6: 22.481846 | T6: 10.395673 | U6: 13.879195 | V6: 0 | W6: 0 | X6: 0 | Y6: 58.382975 | Z6: 14.578841 | AA6: 122.70358 | AB6: 0 | AC6: 4.4504834 | AD6: 30.667872 | AE6: 0 | AF6: 63.797452 | AG6: 3.461258 | AH6: 0 | AI6: 61.099649 | AJ6: 56.421951 | AK6: 9.3335469 | AL6: 0 | AM6: 0 | AN6: 0 | AO6: 4.7763971 | AP6: 1.0650326 | AQ6: 0 | AR6: 3.62881 | AS6: 2.4047923 | AT6: 24.862685 | AU6: 0.86675784 | AV6: 6.3703897 | AW6: 0.92973845 | AX6: 0.63308136 | AY6: 68.174637 | AZ6: 0 | BA6: 3.2130198 | BB6: 37.936628 | BC6: 0 | BD6: 3.3037332 | BE6: 0 | BF6: 0 | BG6: 0 | BH6: 138.6884 | BI6: 0 | BJ6: 0 | BK6: 0 | BL6: 0 | BM6: 0 | BN6: 0 | BO6: 0 | BP6: 0 | BQ6: 73.299494 | BR6: 40.19687 | BS6: 33.988108 | BT6: 29.780134 | BU6: 0 | BV6: 0 | BW6: 0 | BX6: 0 | BY6: 0 | BZ6: 0 | CA6: 0 | CB6: 0 | CC6: 0 | CD6: 0 | CE6: 4.02683 | CF6: 0 | CG6: 0 | CH6: 0 | CI6: 21.965864 | CJ6: 20.995397 | CK6: 61.582691 | CL6: 6.7272039 | CM6: 25.292987 | CN6: 5.7968199 | CO6: 1.2642565 | CP6: 0 | CQ6: 25.150548 | CR6: 15.941614 | CS6: 18.006896 | CT6: 90.340661 | CU6: 33.476075 | CV6: 25.219722 | CW6: 6.4507881 | CX6: 6.8423853 | CY6: 2.463696 | CZ6: 2.8590452 | DA6: 61.216775 | DB6: 11.929207 | DC6: 13.215034 | DD6: 3.9018723 | DE6: 8.7507523 | DF6: 6.5332347 | DG6: 3.6450204 | DH6: 21.737444 | DI6: 4.7414862 | DJ6: 0 | DK6: 0 | DL6: 0 | DM6: 71.001297 | DN6: 12.71675 | DO6: 7.4887874 | DP6: 26.08877 | DQ6: 73.349182 | DR6: 15.505511 | DS6: 173.44904 | DT6: 53.381662 | DU6: 17.005805 | DV6: 13.099644 | DW6: 0 | DX6: 0 | DY6: 0 | DZ6: 0 | EA6: 0 | EB6: 0 | EC6: 0 | ED6: 0 | EE6: 13.58332 | EF6: 17.376125 | EG6: 301.56429 | EH6: 662.94928 | EI6: 0 | EJ6: 0 | EK6: 0 | EL6: 0 | EM6: 0 | EN6: 0 | EO6: 94.946748 | EP6: 0 | EQ6: 0 | ER6: 0.16905365 | ES6: 0 | ET6: 40.437292 | EU6: 355.492 | EV6: 67.921801 | EW6: 60.466327
B7: 2 | D7: Internal | E7: All Scope 2 LB | F7: 5832.2143 | G7: 0 | H7: 0 | I7: 165.39869 | J7: 41.257148 | K7: 0 | L7: 96.247731 | M7: 8.466403 | N7: 25.573495 | O7: 0 | P7: 0 | Q7: 19.604748 | R7: 10.041526 | S7: 22.481846 | T7: 10.395673 | U7: 13.879195 | V7: 0 | W7: 0 | X7: 0 | Y7: 28.920978 | Z7: 2.4867296 | AA7: 57.624148 | AB7: 0 | AC7: 7.0017712 | AD7: 15.62568 | AE7: 0 | AF7: 32.505633 | AG7: 11.775399 | AH7: 0 | AI7: 58.353325 | AJ7: 45.14072 | AK7: 5.8324688 | AL7: 0 | AM7: 0 | AN7: 0 | AO7: 2.7937267 | AP7: 1.675574 | AQ7: 0 | AR7: 3.62881 | AS7: 0.0281211 | AT7: 337.43962 | AU7: 0.14353938 | AV7: 1.054968 | AW7: 0.15396928 | AX7: 0.1048414 | AY7: 68.174637 | AZ7: 0 | BA7: 3.2130198 | BB7: 20.223195 | BC7: 0 | BD7: 31.448188 | BE7: 0 | BF7: 0 | BG7: 0 | BH7: 83.031067 | BI7: 0 | BJ7: 0 | BK7: 0 | BL7: 0 | BM7: 0 | BN7: 0 | BO7: 0 | BP7: 0 | BQ7: 96.347301 | BR7: 21.428081 | BS7: 18.118324 | BT7: 15.875145 | BU7: 0 | BV7: 0 | BW7: 0 | BX7: 0 | BY7: 0 | BZ7: 0 | CA7: 0 | CB7: 0 | CC7: 0 | CD7: 0 | CE7: 2.6222139 | CF7: 0 | CG7: 0 | CH7: 0 | CI7: 11.709526 | CJ7: 11.192191 | CK7: 32.828399 | CL7: 3.5861267 | CM7: 13.483144 | CN7: 3.0901591 | CO7: 0.67394775 | CP7: 0 | CQ7: 13.407212 | CR7: 8.4981291 | CS7: 9.5990865 | CT7: 48.15865 | CU7: 17.84537 | CV7: 13.444088 | CW7: 3.4387754 | CX7: 3.6475274 | CY7: 1.313343 | CZ7: 1.5240951 | DA7: 32.633337 | DB7: 8.3088661 | DC7: 7.0446485 | DD7: 2.0800036 | DE7: 4.6648365 | DF7: 3.4827259 | DG7: 1.9430814 | DH7: 11.58776 | DI7: 2.5275836 | DJ7: 0 | DK7: 0 | DL7: 0 | DM7: 37.849253 | DN7: 6.7790241 | DO7: 3.9921103 | DP7: 13.907358 | DQ7: 39.10086 | DR7: 27.958673 | DS7: 174.71997 | DT7: 51.229222 | DU7: 15.312588 | DV7: 11.812422 | DW7: 0 | DX7: 0 | DY7: 0 | DZ7: 0 | EA7: 0 | EB7: 0 | EC7: 0 | ED7: 0 | EE7: 13.035617 | EF7: 17.048447 | EG7: 298.29474 | EH7: 2515.132 | EI7: 0 | EJ7: 0 | EK7: 0 | EL7: 0 | EM7: 0 | EN7: 0 | EO7: 162.57693 | EP7: 0 | EQ7: 0 | ER7: 313.15167 | ES7: 0 | ET7: 37.461143 | EU7: 311.79972 | EV7: 63.896299 | EW7: 59.326055
B8: 3 | C8: 1 | D8: Upstream | E8: Purchased goods and services | F8: 176935.41 | G8: 0.8721947 | H8: 2010.3685 | I8: 7647.2866 | J8: 1262.0902 | K8: 15.433206 | L8: 2209.6274 | M8: 29.538877 | N8: 859.01725 | O8: -29.180723 | P8: 139.30915 | Q8: 8316.4093 | R8: 0 | S8: 11663.825 | T8: 1036.6033 | U8: 1233.7951 | V8: 0.16646869 | W8: 26.973066 | X8: -18.18906 | Y8: 2863.2553 | Z8: 426.03582 | AA8: 908.91212 | AB8: 1.8756326 | AC8: 745.37167 | AD8: 465.77633 | AE8: 263.12712 | AF8: 4385.563 | AG8: 2160.1081 | AH8: 7.5213041 | AI8: 5122.6784 | AJ8: 5653.9814 | AK8: 1211.1992 | AL8: 69.083754 | AM8: 1.7456557 | AN8: 7.3613004 | AO8: 109.97745 | AP8: 186.09602 | AQ8: 385.76593 | AR8: 1027.5266 | AS8: 85.289998 | AT8: 4332.8271 | AU8: 89.184021 | AV8: 2567.1051 | AW8: 197.28824 | AX8: 548.28511 | AY8: 1764.6961 | AZ8: -97.108868 | BA8: 2.9498422 | BB8: 1719.616 | BC8: 0.71183374 | BD8: 3349.1334 | BE8: -36.361797 | BF8: 19.307441 | BG8: 131.72537 | BH8: 5793.1111 | BI8: 6.252059 | BJ8: 5.5354051 | BK8: 0.98738488 | BL8: 6.1653801 | BM8: 11.026682 | BN8: 1182.8719 | BO8: 0 | BP8: 0 | BQ8: 1012.3631 | BR8: 2285.934 | BS8: 905.15701 | BT8: 1311.5468 | BU8: -352.30999 | BV8: 0.14167143 | BW8: -206.98527 | BX8: 1.0407747 | BY8: 0 | BZ8: -161.08845 | CA8: 13.219823 | CB8: -16.90234 | CC8: 3.1256798 | CD8: 3.2925178 | CE8: 874.16528 | CF8: -0.058718258 | CG8: 0 | CH8: 0 | CI8: 327.9224 | CJ8: 407.7939 | CK8: 1227.561 | CL8: 321.55196 | CM8: 344.19157 | CN8: 196.63274 | CO8: 15.34475 | CP8: 0 | CQ8: 699.80879 | CR8: 422.45111 | CS8: 475.44476 | CT8: 1235.1104 | CU8: -36.016819 | CV8: 237.30294 | CW8: 379.73902 | CX8: 214.13676 | CY8: 343.96222 | CZ8: 31.530502 | DA8: 1830.1142 | DB8: 138.34436 | DC8: 174.53012 | DD8: 95.047558 | DE8: 214.20053 | DF8: 130.01545 | DG8: 83.899871 | DH8: 369.0978 | DI8: 224.69234 | DJ8: 0.33025397 | DK8: 1.573045 | DL8: 0 | DM8: 621.34634 | DN8: 106.48322 | DO8: 63.124836 | DP8: 435.97491 | DQ8: 187.39171 | DR8: 609.62816 | DS8: 1440.3883 | DT8: 491.94533 | DU8: 1817.2731 | DV8: 1094.8987 | DW8: 19.223449 | DX8: 6.8161928 | DY8: 27.943824 | DZ8: 5.7423369 | EA8: 15.348146 | EB8: 59.571898 | EC8: 11.074176 | ED8: 3.0586101 | EE8: 945.59798 | EF8: 1785.7581 | EG8: 5097.5533 | EH8: 15102.957 | EI8: 426.63942 | EJ8: 423.71104 | EK8: 51.384639 | EL8: -78.231483 | EM8: 26.846844 | EN8: 0 | EO8: 18717.241 | EP8: 184.0452 | EQ8: 137.56175 | ER8: 11780.202 | ES8: 0.037366398 | ET8: 1068.6979 | EU8: 12762.097 | EV8: 259.42519 | EW8: 1360.1896
B9: 3 | C9: 2 | D9: Upstream | E9: Capital goods | F9: 6973.2078 | G9: 0 | H9: 0 | I9: 348.20845 | J9: 34.71215 | K9: 0 | L9: 93.780348 | M9: -10.655506 | N9: 3.1111982 | O9: 0 | P9: 4.6198864 | Q9: 164.84878 | R9: 0 | S9: 2513.8795 | T9: 3.0406871 | U9: 0.98931676 | V9: 0 | W9: 0 | X9: 0 | Y9: 34.156703 | Z9: 3.7576343 | AA9: 132.03883 | AB9: 0 | AC9: 3.1755286 | AD9: 11.155968 | AE9: 0 | AF9: 41.860002 | AG9: 3.3563669 | AH9: 0 | AI9: 56.567215 | AJ9: 46.870157 | AK9: 2.2906976 | AL9: 0 | AM9: 0 | AN9: 0 | AO9: 0 | AP9: 5.0600965 | AQ9: 0 | AR9: 32.169846 | AS9: 0 | AT9: 314.79994 | AU9: 0 | AV9: 60.91277 | AW9: 0 | AX9: 0 | AY9: 72.896653 | AZ9: 0 | BA9: 0.86844155 | BB9: 38.851851 | BC9: 0 | BD9: 36.434441 | BE9: 0 | BF9: 0 | BG9: 0 | BH9: 24.513469 | BI9: 0 | BJ9: 0 | BK9: 0 | BL9: 0 | BM9: 0 | BN9: 0 | BO9: 0 | BP9: 0 | BQ9: 0 | BR9: 1045.4001 | BS9: 0 | BT9: 28.866299 | BU9: 0 | BV9: 0 | BW9: 0 | BX9: 0 | BY9: 0 | BZ9: 0 | CA9: 0 | CB9: 0 | CC9: 0 | CD9: 0 | CE9: 0 | CF9: 0 | CG9: 0 | CH9: 0 | CI9: 21.975727 | CJ9: 19.192587 | CK9: 74.756951 | CL9: 18.912969 | CM9: 6.9732393 | CN9: 10.912111 | CO9: -10.803325 | CP9: 0 | CQ9: 0.52626622 | CR9: 7.3713153 | CS9: 2.9622342 | CT9: 99.629711 | CU9: 0 | CV9: 14.322131 | CW9: 9.3869463 | CX9: 14.787441 | CY9: 0 | CZ9: 0 | DA9: 80.846966 | DB9: 2.0807742 | DC9: 0 | DD9: 0 | DE9: 0 | DF9: 0 | DG9: 0 | DH9: 64.669516 | DI9: 63.066634 | DJ9: 0 | DK9: 0 | DL9: 0 | DM9: 0 | DN9: 0 | DO9: 0 | DP9: 0 | DQ9: 72.225444 | DR9: 0 | DS9: 132.94017 | DT9: 15.797961 | DU9: 44.846276 | DV9: 0 | DW9: 0 | DX9: 0 | DY9: 0 | DZ9: 0 | EA9: 0 | EB9: 0 | EC9: 0 | ED9: 0 | EE9: 5.8449131 | EF9: 46.045781 | EG9: 0 | EH9: 638.64136 | EI9: 0 | EJ9: 0 | EK9: 0 | EL9: 0 | EM9: 0 | EN9: 0 | EO9: 34.878088 | EP9: 0 | EQ9: 0 | ER9: 193.02898 | ES9: 0 | ET9: 10.59269 | EU9: 124.25809 | EV9: 0 | EW9: 0
